Workbook

Sheet 📋 Petunjuk
B1: DISC PERSONALITY TEST
B4: Easy Legal — Assessment Rekrutmen 2024
B6: DATA KANDIDAT
B7: Nama Kandidat : ______________________________________
B8: Posisi yang Dilamar : ______________________________________
B9: Tanggal : ______________________________________
B10: Penilai / HR : ______________________________________
B12: PETUNJUK PENGISIAN
B13: 1. Tes ini terdiri dari 28 kelompok kata sifat (4 kata per kelompok).
B14: 2. Di setiap kelompok, pilih 1 kata yang PALING menggambarkan Anda (kolom M = Most).
B15: 3. Di setiap kelompok, pilih 1 kata yang PALING TIDAK menggambarkan Anda (kolom L = Least).
B16: 4. Setiap kelompok harus memiliki tepat 1 jawaban M dan 1 jawaban L.
... B35: → Lanjut ke sheet '📝 DISC Test' untuk mengisi jawaban

Sheet 📝 DISC Test
A1: DISC TEST — EASY LEGAL RECRUITMENT
A2: Tandai kolom M (Most) = paling menggambarkan Anda | Tandai kolom L (Least) = paling tidak menggambarkan Anda | Isi dengan huruf X
A3: No | B3: Kata Sifat | C3: M (Paling Sesuai) | D3: L (Paling Tidak Sesuai) | E3: Tipe | G3: No | H3: Kata Sifat | I3: M (Paling Sesuai) | J3: L (Paling Tidak Sesuai) | K3: Tipe
A4: 1.1 | B4: Kuat | E4: D | G4: 15.1 | H4: Keras | K4: D
B5: Menyenangkan | E5: I | H5: Ceria | K5: I
B6: Setia | E6: S | H6: Toleran | K6: S
B7: Tepat | E7: C | H7: Disiplin | K7: C
A8: 2.1 | B8: Berani | E8: D | G8: 16.1 | H8: Penuh Tekad | K8: D
B9: Antusias | E9: I | H9: Spontan | K9: I
B10: Tenang | E10: S | H10: Pendengar | K10: S
B11: Teliti | E11: C | H11: Teratur | K11: C
A12: 3.1 | B12: Dominan | E12: D | G12: 17.1 | H12: Agresif | K12: D
B13: Berpengaruh | E13: I | H13: Terbuka | K13: I
B14: Sabar | E14: S | H14: Lembut | K14: S
B15: Hati-hati | E15: C | H15: Cermat | K15: C
A16: 4.1 | B16: Tegas | E16: D | G16: 18.1 | H16: Cepat | K16: D
B17: Ramah | E17: I | H17: Antusias | K17: I
B18: Kooperatif | E18: S | H18: Santai | K18: S
B19: Akurat | E19: C | H19: Hati-hati | K19: C
A20: 5.1 | B20: Mandiri | E20: D | G20: 19.1 | H20: Keras Kepala | K20: D
B21: Persuasif | E21: I | H21: Dramatis | K21: I
B22: Konsisten | E22: S | H22: Menolong | K22: S
B23: Analitis | E23: C | H23: Sistemik | K23: C
A24: 6.1 | B24: Kompetitif | E24: D | G24: 20.1 | H24: Berorientasi Tujuan | K24: D
B25: Optimis | E25: I | H25: Meyakinkan | K25: I
B26: Dapat Diandalkan | E26: S | H26: Terduga | K26: S
B27: Perfeksionis | E27: C | H27: Analitis | K27: C
A28: 7.1 | B28: Langsung | E28: D | G28: 21.1 | H28: Risk Taker | K28: D
B29: Ekspresif | E29: I | H29: Ceria | K29: I
B30: Stabil | E30: S | H30: Berhati-hati | K30: S
B31: Sistematis | E31: C | H31: Akurat | K31: C
A32: 8.1 | B32: Menantang | E32: D | G32: 22.1 | H32: Pemimpin | K32: D
B33: Inspiratif | E33: I | H33: Populer | K33: I
B34: Sabar | E34: S | H34: Setia Kawan | K34: S
B35: Logis | E35: C | H35: Bijaksana | K35: C
A36: 9.1 | B36: Hasil-oriented | E36: D | G36: 23.1 | H36: Proaktif | K36: D
B37: Sosial | E37: I | H37: Antusias | K37: I
B38: Loyal | E38: S | H38: Suportif | K38: S
B39: Kritis | E39: C | H39: Faktual | K39: C
A40: 10.1 | B40: Berinisiatif | E40: D | G40: 24.1 | H40: Otoriter | K40: D
...

Sheet 📊 Hasil & Analisa
A1: HASIL DISC TEST — ANALISA & REKOMENDASI POSISI
A2: Easy Legal | HR Recruitment Assessment Tool
B4: BAGIAN A — SKOR MENTAH (Raw Score)
B5: Dimensi | C5: M Score | D5: L Score | E5: Net Score | F5: % Total
B6: D — Dominance | C6: =COUNTIFS('📝 DISC Test'!E4:E59,"D",'📝 DISC Test'!C4:C59,"X")+COUNTIFS('📝 DISC Test'!K4:K59,"D",'📝 DISC Test'!I4:I59,"X") -> 0 | D6: =COUNTIFS('📝 DISC Test'!E4:E59,"D",'📝 DISC Test'!D4:D59,"X")+COUNTIFS('📝 DISC Test'!K4:K59,"D",'📝 DISC Test'!J4:J59,"X") -> 0 | E6: =C6-D6 -> 0 | F6: =IF(SUM(E6:E9)<>0,E6/SUM($E$6:$E$9),0) -> 0
B7: I — Influence | C7: =COUNTIFS('📝 DISC Test'!E4:E59,"I",'📝 DISC Test'!C4:C59,"X")+COUNTIFS('📝 DISC Test'!K4:K59,"I",'📝 DISC Test'!I4:I59,"X") -> 0 | D7: =COUNTIFS('📝 DISC Test'!E4:E59,"I",'📝 DISC Test'!D4:D59,"X")+COUNTIFS('📝 DISC Test'!K4:K59,"I",'📝 DISC Test'!J4:J59,"X") -> 0 | E7: =C7-D7 -> 0 | F7: =IF(SUM(E6:E9)<>0,E7/SUM($E$6:$E$9),0) -> 0
B8: S — Steadiness | C8: =COUNTIFS('📝 DISC Test'!E4:E59,"S",'📝 DISC Test'!C4:C59,"X")+COUNTIFS('📝 DISC Test'!K4:K59,"S",'📝 DISC Test'!I4:I59,"X") -> 0 | D8: =COUNTIFS('📝 DISC Test'!E4:E59,"S",'📝 DISC Test'!D4:D59,"X")+COUNTIFS('📝 DISC Test'!K4:K59,"S",'📝 DISC Test'!J4:J59,"X") -> 0 | E8: =C8-D8 -> 0 | F8: =IF(SUM(E6:E9)<>0,E8/SUM($E$6:$E$9),0) -> 0
B9: C — Conscientiousness | C9: =COUNTIFS('📝 DISC Test'!E4:E59,"C",'📝 DISC Test'!C4:C59,"X")+COUNTIFS('📝 DISC Test'!K4:K59,"C",'📝 DISC Test'!I4:I59,"X") -> 0 | D9: =COUNTIFS('📝 DISC Test'!E4:E59,"C",'📝 DISC Test'!D4:D59,"X")+COUNTIFS('📝 DISC Test'!K4:K59,"C",'📝 DISC Test'!J4:J59,"X") -> 0 | E9: =C9-D9 -> 0 | F9: =IF(SUM(E6:E9)<>0,E9/SUM($E$6:$E$9),0) -> 0
B10: TOTAL | C10: =SUM(C6:C9) -> 0 | D10: =SUM(D6:D9) -> 0 | E10: =SUM(E6:E9) -> 0 | F10: 100%
B12: BAGIAN B — PROFIL DOMINAN
B13: Tipe Primer: | C13: =IF(MAX(E6:E9)=E6,"D — Dominance",IF(MAX(E6:E9)=E7,"I — Influence",IF(MAX(E6:E9)=E8,"S — Steadiness","C — Conscientiousness"))) -> D — Dominance
B14: Tipe Sekunder: | C14: =IF(LARGE(E6:E9,2)=E6,"D — Dominance",IF(LARGE(E6:E9,2)=E7,"I — Influence",IF(LARGE(E6:E9,2)=E8,"S — Steadiness","C — Conscientiousness"))) -> D — Dominance
B16: BAGIAN C — ANALISA KESESUAIAN POSISI
B17: Posisi | C17: Skor Fit (%) | D17: Status | E17: Catatan HR
B18: Legal Officer (LO) | C18: =ROUND((F9*0.5 + F6*0.3 + (1-F7)*0.1 + (1-F8)*0.1)*100,1) -> 20 | D18: =IF(C18>=70,"✅ SANGAT COCOK",IF(C18>=55,"🟡 CUKUP COCOK","❌ KURANG COCOK")) -> ❌ KURANG COCOK | E18: C dominan (akurat, sistematis) + D mendukung (decisive)
B19: Customer Care / CRM | C19: =ROUND((F7*0.5 + F8*0.3 + (1-F6)*0.1 + (1-F9)*0.1)*100,1) -> 20 | D19: =IF(C19>=70,"✅ SANGAT COCOK",IF(C19>=55,"🟡 CUKUP COCOK","❌ KURANG COCOK")) -> ❌ KURANG COCOK | E19: I dominan (komunikatif) + S mendukung (sabar, empati)
B20: PLA (Pre-Closing Lead Agent) | C20: =ROUND((F6*0.45 + F7*0.35 + (1-F8)*0.1 + (1-F9)*0.1)*100,1) -> 20 | D20: =IF(C20>=70,"✅ SANGAT COCOK",IF(C20>=55,"🟡 CUKUP COCOK","❌ KURANG COCOK")) -> ❌ KURANG COCOK | E20: D+I dominan (agresif, persuasif, target-driven)
B21: Marketing | C21: =ROUND((F7*0.5 + F6*0.3 + (1-F8)*0.1 + (1-F9)*0.1)*100,1) -> 20 | D21: =IF(C21>=70,"✅ SANGAT COCOK",IF(C21>=55,"🟡 CUKUP COCOK","❌ KURANG COCOK")) -> ❌ KURANG COCOK | E21: I dominan (kreatif, storytelling) + D mendukung (driven)
B23: BAGIAN D — REKOMENDASI FINAL HR
B24: Posisi Paling Direkomendasikan: | C24: =IF(MAX(C18:C21)=C18,"Legal Officer (LO)",IF(MAX(C18:C21)=C19,"Customer Care / CRM",IF(MAX(C18:C21)=C20,"PLA (Pre-Closing Lead Agent)","Marketing"))) -> Legal Officer (LO)
B25: Skor Fit Posisi Terpilih: | C25: =MAX(C18:C21) -> 20
B27: CATATAN TAMBAHAN HR:
B34: ⚠️ DISC adalah alat bantu seleksi, bukan penentu tunggal. Kombinasikan dengan wawancara mendalam, tes kemampuan, & referensi.

Sheet 🎯 Panduan Rekrutmen
B1: PANDUAN REKRUTMEN — EASY LEGAL
B2: Standar Seleksi Kandidat per Posisi | Dibuat oleh HR Direktur
B4: ⚖️ LEGAL OFFICER (LO)
B5: Target KPI | C5: 60-100 project legalitas per bulan (PT, CV, Perizinan, dll)
B6: DISC Ideal | C6: C Primer (≥40%) + D Sekunder (≥20%) | Rendah I & S
B7: Hard Skill Wajib | C7: Pemahaman hukum perusahaan, OSS/NIB, Akte Notaris, perizinan sektoral
B8: Soft Skill Wajib | C8: Manajemen dokumen, multi-tasking, teliti, deadline-oriented
B9: Pendidikan Min. | C9: S1 Hukum / D3 Hukum + pengalaman relevan ≥1 tahun
B10: Test Tambahan | C10: ✅ Tes IQ (min. 110) | ✅ Tes teliti/ketelitian dokumen | ✅ Simulasi pengerjaan berkas
B11: Red Flag DISC | C11: I sangat tinggi (>45%) — terlalu sosial, kurang detail-oriented
B12: Interview Focus | C12: Bagaimana kamu handle 80 project bersamaan? Ceritakan sistem kerjamu.
B14: 🎧 CUSTOMER CARE (CRM & PLA)
B15: Scope Tugas | C15: Handle lead inbound, follow-up WhatsApp/email, closing awal, kelola komplain
B16: DISC CRM Ideal | C16: I Primer (≥35%) + S Sekunder (≥25%) | CRM: sabar, empati, relationship builder
B17: DISC PLA Ideal | C17: D Primer (≥35%) + I Sekunder (≥30%) | PLA: agresif closing, target-driven
B18: Hard Skill CRM | C18: CRM tools (HubSpot/Notion/Spreadsheet), komunikasi tertulis & lisan profesional
B19: Hard Skill PLA | C19: Teknik closing, objection handling, pipeline management, target closing rate ≥30%
B20: Soft Skill Wajib | C20: Empati, sabar, komunikasi persuasif, tidak mudah menyerah, multitasking
B21: Test Tambahan | C21: ✅ Tes IQ (min. 100) | ✅ Role play handling komplain | ✅ Simulasi cold calling/WA
B22: Red Flag DISC | C22: C sangat tinggi (>50%) — terlalu kaku untuk handle klien emosional
B23: Interview CRM | C23: Ceritakan pengalaman handling klien marah. Apa yang kamu lakukan?
B24: Interview PLA | C24: Bagaimana strategimu follow-up lead yang sudah 3x tidak respon?
B26: 🧠 REKOMENDASI TES IQ — EASY LEGAL
B27: Apakah perlu IQ test? | C27: ✅ YA, sangat direkomendasikan untuk LO (kritis) dan PLA (problem solving cepat)
B28: Standar Minimum LO | C28: IQ ≥ 110 (Di atas rata-rata) — butuh kemampuan analisis dokumen kompleks
B29: Standar Minimum CC/PLA | C29: IQ ≥ 100 (Rata-rata) — butuh kemampuan komunikasi & problem solving dasar
B30: Standar Minimum Marketing | C30: IQ ≥ 105 — kreativitas + logika campaign
B31: Aplikasi Gratis | C31: ➊ Kraepelin / Pauli Test (konsentrasi & ketelitian) — cocok untuk LO
C32: ➋ Psikotes.id — platform lokal, free tier tersedia, cocok UMKM
C33: ➌ TestDome.com — berbasis kompetensi + IQ, bisa custom
B34: Aplikasi Berbayar | C34: ➊ Talenta.co (HR platform Indonesia, sudah include psikotes)
C35: ➋ GrowthHackers Psikotes — sudah termasuk DISC + IQ + Big5
C36: ➌ AssessFirst — enterprise-level, akurasi tinggi, ada DISC + cognitive
B37: Rekomendasi Terbaik UMKM | C37: 🏆 Psikotes.id atau Talenta.co — biaya terjangkau, antarmuka Bahasa Indonesia
B39: 📌 CATATAN: DISC + IQ + Wawancara Terstruktur = Kombinasi terbaik untuk seleksi kandidat berkualitas di Easy Legal

Sheet 📥 Input Skor GForm
A1: INPUT SKOR DISC — FORMAT GOOGLE FORM / ANGKA LANGSUNG
A2: Easy Legal | Masukkan skor D, S, C, I dari hasil GForm — Analisa otomatis muncul di kolom kanan
A4: SKALA PENILAIAN (Threshold)
A5: Rentang | B5: Level | C5: Interpretasi
A6: < 9 | B6: RENDAH | C6: Dimensi ini bukan karakter dominan kandidat
A7: 9 – 13 | B7: SEDANG | C7: Dimensi ini cukup ada, tapi bukan yang utama
A8: 14 – 17 | B8: TINGGI | C8: Dimensi ini menonjol dan berpengaruh signifikan
A9: ≥ 18 | B9: SANGAT TINGGI | C9: Dimensi ini sangat dominan — karakter utama kandidat
A11: No | B11: Nama Kandidat | C11: Posisi Dilamar | D11: Skor D (Dominance) | E11: Skor S (Steadiness) | F11: Skor C (Conscient.) | G11: Skor I (Influence) | H11: Level D | I11: Level S | J11: Level C | K11: Level I
A12: 1 | B12: Tiara Nabila | C12: Easy Legal | D12: 7 | E12: 20 | F12: 8 | G12: 6 | H12: =IF(D12="","—",IF(D12<9,"🔴 Rendah",IF(D12<=13,"🟡 Sedang",IF(D12<=17,"🟢 Tinggi","🔵 Sangat Tinggi")))) -> 🔴 Rendah | I12: =IF(E12="","—",IF(E12<9,"🔴 Rendah",IF(E12<=13,"🟡 Sedang",IF(E12<=17,"🟢 Tinggi","🔵 Sangat Tinggi")))) -> 🔵 Sangat Tinggi | J12: =IF(F12="","—",IF(F12<9,"🔴 Rendah",IF(F12<=13,"🟡 Sedang",IF(F12<=17,"🟢 Tinggi","🔵 Sangat Tinggi")))) -> 🔴 Rendah | K12: =IF(G12="","—",IF(G12<9,"🔴 Rendah",IF(G12<=13,"🟡 Sedang",IF(G12<=17,"🟢 Tinggi","🔵 Sangat Tinggi")))) -> 🔴 Rendah
A13: 2 | B13: Amnila Hanisah Rifainy | C13: Easy Legal | D13: 3 | E13: 20 | F13: 14 | G13: 7 | H13: =IF(D13="","—",IF(D13<9,"🔴 Rendah",IF(D13<=13,"🟡 Sedang",IF(D13<=17,"🟢 Tinggi","🔵 Sangat Tinggi")))) -> 🔴 Rendah | I13: =IF(E13="","—",IF(E13<9,"🔴 Rendah",IF(E13<=13,"🟡 Sedang",IF(E13<=17,"🟢 Tinggi","🔵 Sangat Tinggi")))) -> 🔵 Sangat Tinggi | J13: =IF(F13="","—",IF(F13<9,"🔴 Rendah",IF(F13<=13,"🟡 Sedang",IF(F13<=17,"🟢 Tinggi","🔵 Sangat Tinggi")))) -> 🟢 Tinggi | K13: =IF(G13="","—",IF(G13<9,"🔴 Rendah",IF(G13<=13,"🟡 Sedang",IF(G13<=17,"🟢 Tinggi","🔵 Sangat Tinggi")))) -> 🔴 Rendah
A14: 3 | B14: Fika Nur Fatmala | C14: Easy Legal | D14: 4 | E14: 16 | F14: 14 | G14: 8 | H14: =IF(D14="","—",IF(D14<9,"🔴 Rendah",IF(D14<=13,"🟡 Sedang",IF(D14<=17,"🟢 Tinggi","🔵 Sangat Tinggi")))) -> 🔴 Rendah | I14: =IF(E14="","—",IF(E14<9,"🔴 Rendah",IF(E14<=13,"🟡 Sedang",IF(E14<=17,"🟢 Tinggi","🔵 Sangat Tinggi")))) -> 🟢 Tinggi | J14: =IF(F14="","—",IF(F14<9,"🔴 Rendah",IF(F14<=13,"🟡 Sedang",IF(F14<=17,"🟢 Tinggi","🔵 Sangat Tinggi")))) -> 🟢 Tinggi | K14: =IF(G14="","—",IF(G14<9,"🔴 Rendah",IF(G14<=13,"🟡 Sedang",IF(G14<=17,"🟢 Tinggi","🔵 Sangat Tinggi")))) -> 🔴 Rendah
A15: 4 | B15: Fauzia Rahmawati | C15: Easy Legal | D15: 3 | E15: 16 | F15: 12 | G15: 10 | H15: =IF(D15="","—",IF(D15<9,"🔴 Rendah",IF(D15<=13,"🟡 Sedang",IF(D15<=17,"🟢 Tinggi","🔵 Sangat Tinggi")))) -> 🔴 Rendah | I15: =IF(E15="","—",IF(E15<9,"🔴 Rendah",IF(E15<=13,"🟡 Sedang",IF(E15<=17,"🟢 Tinggi","🔵 Sangat Tinggi")))) -> 🟢 Tinggi | J15: =IF(F15="","—",IF(F15<9,"🔴 Rendah",IF(F15<=13,"🟡 Sedang",IF(F15<=17,"🟢 Tinggi","🔵 Sangat Tinggi")))) -> 🟡 Sedang | K15: =IF(G15="","—",IF(G15<9,"🔴 Rendah",IF(G15<=13,"🟡 Sedang",IF(G15<=17,"🟢 Tinggi","🔵 Sangat Tinggi")))) -> 🟡 Sedang
A16: 5 | B16: SALMAN ARYANA | C16: Easy Legal | D16: 10 | E16: 15 | F16: 12 | G16: 4 | H16: =IF(D16="","—",IF(D16<9,"🔴 Rendah",IF(D16<=13,"🟡 Sedang",IF(D16<=17,"🟢 Tinggi","🔵 Sangat Tinggi")))) -> 🟡 Sedang | I16: =IF(E16="","—",IF(E16<9,"🔴 Rendah",IF(E16<=13,"🟡 Sedang",IF(E16<=17,"🟢 Tinggi","🔵 Sangat Tinggi")))) -> 🟢 Tinggi | J16: =IF(F16="","—",IF(F16<9,"🔴 Rendah",IF(F16<=13,"🟡 Sedang",IF(F16<=17,"🟢 Tinggi","🔵 Sangat Tinggi")))) -> 🟡 Sedang | K16: =IF(G16="","—",IF(G16<9,"🔴 Rendah",IF(G16<=13,"🟡 Sedang",IF(G16<=17,"🟢 Tinggi","🔵 Sangat Tinggi")))) -> 🔴 Rendah
A17: 6 | B17: Wulan Eka Refiana | C17: Easy Legal | D17: 6 | E17: 15 | F17: 16 | G17: 4 | H17: =IF(D17="","—",IF(D17<9,"🔴 Rendah",IF(D17<=13,"🟡 Sedang",IF(D17<=17,"🟢 Tinggi","🔵 Sangat Tinggi")))) -> 🔴 Rendah | I17: =IF(E17="","—",IF(E17<9,"🔴 Rendah",IF(E17<=13,"🟡 Sedang",IF(E17<=17,"🟢 Tinggi","🔵 Sangat Tinggi")))) -> 🟢 Tinggi | J17: =IF(F17="","—",IF(F17<9,"🔴 Rendah",IF(F17<=13,"🟡 Sedang",IF(F17<=17,"🟢 Tinggi","🔵 Sangat Tinggi")))) -> 🟢 Tinggi | K17: =IF(G17="","—",IF(G17<9,"🔴 Rendah",IF(G17<=13,"🟡 Sedang",IF(G17<=17,"🟢 Tinggi","🔵 Sangat Tinggi")))) -> 🔴 Rendah
A18: 7 | B18: Mulyanasari (Riri) | C18: Easy Legal | D18: 4 | E18: 15 | F18: 16 | G18: 6 | H18: =IF(D18="","—",IF(D18<9,"🔴 Rendah",IF(D18<=13,"🟡 Sedang",IF(D18<=17,"🟢 Tinggi","🔵 Sangat Tinggi")))) -> 🔴 Rendah | I18: =IF(E18="","—",IF(E18<9,"🔴 Rendah",IF(E18<=13,"🟡 Sedang",IF(E18<=17,"🟢 Tinggi","🔵 Sangat Tinggi")))) -> 🟢 Tinggi | J18: =IF(F18="","—",IF(F18<9,"🔴 Rendah",IF(F18<=13,"🟡 Sedang",IF(F18<=17,"🟢 Tinggi","🔵 Sangat Tinggi")))) -> 🟢 Tinggi | K18: =IF(G18="","—",IF(G18<9,"🔴 Rendah",IF(G18<=13,"🟡 Sedang",IF(G18<=17,"🟢 Tinggi","🔵 Sangat Tinggi")))) -> 🔴 Rendah
A19: 8 | B19: yumita | C19: Easy Legal | D19: 7 | E19: 14 | F19: 11 | G19: 9 | H19: =IF(D19="","—",IF(D19<9,"🔴 Rendah",IF(D19<=13,"🟡 Sedang",IF(D19<=17,"🟢 Tinggi","🔵 Sangat Tinggi")))) -> 🔴 Rendah | I19: =IF(E19="","—",IF(E19<9,"🔴 Rendah",IF(E19<=13,"🟡 Sedang",IF(E19<=17,"🟢 Tinggi","🔵 Sangat Tinggi")))) -> 🟢 Tinggi | J19: =IF(F19="","—",IF(F19<9,"🔴 Rendah",IF(F19<=13,"🟡 Sedang",IF(F19<=17,"🟢 Tinggi","🔵 Sangat Tinggi")))) -> 🟡 Sedang | K19: =IF(G19="","—",IF(G19<9,"🔴 Rendah",IF(G19<=13,"🟡 Sedang",IF(G19<=17,"🟢 Tinggi","🔵 Sangat Tinggi")))) -> 🟡 Sedang
A20: 9 | B20: Ela Yuniar | C20: Easy Legal | D20: 3 | E20: 14 | F20: 15 | G20: 9 | H20: =IF(D20="","—",IF(D20<9,"🔴 Rendah",IF(D20<=13,"🟡 Sedang",IF(D20<=17,"🟢 Tinggi","🔵 Sangat Tinggi")))) -> 🔴 Rendah | I20: =IF(E20="","—",IF(E20<9,"🔴 Rendah",IF(E20<=13,"🟡 Sedang",IF(E20<=17,"🟢 Tinggi","🔵 Sangat Tinggi")))) -> 🟢 Tinggi | J20: =IF(F20="","—",IF(F20<9,"🔴 Rendah",IF(F20<=13,"🟡 Sedang",IF(F20<=17,"🟢 Tinggi","🔵 Sangat Tinggi")))) -> 🟢 Tinggi | K20: =IF(G20="","—",IF(G20<9,"🔴 Rendah",IF(G20<=13,"🟡 Sedang",IF(G20<=17,"🟢 Tinggi","🔵 Sangat Tinggi")))) -> 🟡 Sedang
A21: 10 | B21: yunia raventi | C21: Easy Legal | D21: 3 | E21: 14 | F21: 15 | G21: 9 | H21: =IF(D21="","—",IF(D21<9,"🔴 Rendah",IF(D21<=13,"🟡 Sedang",IF(D21<=17,"🟢 Tinggi","🔵 Sangat Tinggi")))) -> 🔴 Rendah | I21: =IF(E21="","—",IF(E21<9,"🔴 Rendah",IF(E21<=13,"🟡 Sedang",IF(E21<=17,"🟢 Tinggi","🔵 Sangat Tinggi")))) -> 🟢 Tinggi | J21: =IF(F21="","—",IF(F21<9,"🔴 Rendah",IF(F21<=13,"🟡 Sedang",IF(F21<=17,"🟢 Tinggi","🔵 Sangat Tinggi")))) -> 🟢 Tinggi | K21: =IF(G21="","—",IF(G21<9,"🔴 Rendah",IF(G21<=13,"🟡 Sedang",IF(G21<=17,"🟢 Tinggi","🔵 Sangat Tinggi")))) -> 🟡 Sedang
A22: 11 | B22: AULIA AZMI IZZATUL HAQ | C22: Easy Legal | D22: 4 | E22: 13 | F22: 21 | G22: 3 | H22: =IF(D22="","—",IF(D22<9,"🔴 Rendah",IF(D22<=13,"🟡 Sedang",IF(D22<=17,"🟢 Tinggi","🔵 Sangat Tinggi")))) -> 🔴 Rendah | I22: =IF(E22="","—",IF(E22<9,"🔴 Rendah",IF(E22<=13,"🟡 Sedang",IF(E22<=17,"🟢 Tinggi","🔵 Sangat Tinggi")))) -> 🟡 Sedang | J22: =IF(F22="","—",IF(F22<9,"🔴 Rendah",IF(F22<=13,"🟡 Sedang",IF(F22<=17,"🟢 Tinggi","🔵 Sangat Tinggi")))) -> 🔵 Sangat Tinggi | K22: =IF(G22="","—",IF(G22<9,"🔴 Rendah",IF(G22<=13,"🟡 Sedang",IF(G22<=17,"🟢 Tinggi","🔵 Sangat Tinggi")))) -> 🔴 Rendah
A23: 12 | H23: =IF(D23="","—",IF(D23<9,"🔴 Rendah",IF(D23<=13,"🟡 Sedang",IF(D23<=17,"🟢 Tinggi","🔵 Sangat Tinggi")))) -> — | I23: =IF(E23="","—",IF(E23<9,"🔴 Rendah",IF(E23<=13,"🟡 Sedang",IF(E23<=17,"🟢 Tinggi","🔵 Sangat Tinggi")))) -> — | J23: =IF(F23="","—",IF(F23<9,"🔴 Rendah",IF(F23<=13,"🟡 Sedang",IF(F23<=17,"🟢 Tinggi","🔵 Sangat Tinggi")))) -> — | K23: =IF(G23="","—",IF(G23<9,"🔴 Rendah",IF(G23<=13,"🟡 Sedang",IF(G23<=17,"🟢 Tinggi","🔵 Sangat Tinggi")))) -> —
A24: 13 | H24: =IF(D24="","—",IF(D24<9,"🔴 Rendah",IF(D24<=13,"🟡 Sedang",IF(D24<=17,"🟢 Tinggi","🔵 Sangat Tinggi")))) -> — | I24: =IF(E24="","—",IF(E24<9,"🔴 Rendah",IF(E24<=13,"🟡 Sedang",IF(E24<=17,"🟢 Tinggi","🔵 Sangat Tinggi")))) -> — | J24: =IF(F24="","—",IF(F24<9,"🔴 Rendah",IF(F24<=13,"🟡 Sedang",IF(F24<=17,"🟢 Tinggi","🔵 Sangat Tinggi")))) -> — | K24: =IF(G24="","—",IF(G24<9,"🔴 Rendah",IF(G24<=13,"🟡 Sedang",IF(G24<=17,"🟢 Tinggi","🔵 Sangat Tinggi")))) -> —
A25: 14 | H25: =IF(D25="","—",IF(D25<9,"🔴 Rendah",IF(D25<=13,"🟡 Sedang",IF(D25<=17,"🟢 Tinggi","🔵 Sangat Tinggi")))) -> — | I25: =IF(E25="","—",IF(E25<9,"🔴 Rendah",IF(E25<=13,"🟡 Sedang",IF(E25<=17,"🟢 Tinggi","🔵 Sangat Tinggi")))) -> — | J25: =IF(F25="","—",IF(F25<9,"🔴 Rendah",IF(F25<=13,"🟡 Sedang",IF(F25<=17,"🟢 Tinggi","🔵 Sangat Tinggi")))) -> — | K25: =IF(G25="","—",IF(G25<9,"🔴 Rendah",IF(G25<=13,"🟡 Sedang",IF(G25<=17,"🟢 Tinggi","🔵 Sangat Tinggi")))) -> —
A26: 15 | H26: =IF(D26="","—",IF(D26<9,"🔴 Rendah",IF(D26<=13,"🟡 Sedang",IF(D26<=17,"🟢 Tinggi","🔵 Sangat Tinggi")))) -> — | I26: =IF(E26="","—",IF(E26<9,"🔴 Rendah",IF(E26<=13,"🟡 Sedang",IF(E26<=17,"🟢 Tinggi","🔵 Sangat Tinggi")))) -> — | J26: =IF(F26="","—",IF(F26<9,"🔴 Rendah",IF(F26<=13,"🟡 Sedang",IF(F26<=17,"🟢 Tinggi","🔵 Sangat Tinggi")))) -> — | K26: =IF(G26="","—",IF(G26<9,"🔴 Rendah",IF(G26<=13,"🟡 Sedang",IF(G26<=17,"🟢 Tinggi","🔵 Sangat Tinggi")))) -> —
A27: 16 | H27: =IF(D27="","—",IF(D27<9,"🔴 Rendah",IF(D27<=13,"🟡 Sedang",IF(D27<=17,"🟢 Tinggi","🔵 Sangat Tinggi")))) -> — | I27: =IF(E27="","—",IF(E27<9,"🔴 Rendah",IF(E27<=13,"🟡 Sedang",IF(E27<=17,"🟢 Tinggi","🔵 Sangat Tinggi")))) -> — | J27: =IF(F27="","—",IF(F27<9,"🔴 Rendah",IF(F27<=13,"🟡 Sedang",IF(F27<=17,"🟢 Tinggi","🔵 Sangat Tinggi")))) -> — | K27: =IF(G27="","—",IF(G27<9,"🔴 Rendah",IF(G27<=13,"🟡 Sedang",IF(G27<=17,"🟢 Tinggi","🔵 Sangat Tinggi")))) -> —
A28: 17 | H28: =IF(D28="","—",IF(D28<9,"🔴 Rendah",IF(D28<=13,"🟡 Sedang",IF(D28<=17,"🟢 Tinggi","🔵 Sangat Tinggi")))) -> — | I28: =IF(E28="","—",IF(E28<9,"🔴 Rendah",IF(E28<=13,"🟡 Sedang",IF(E28<=17,"🟢 Tinggi","🔵 Sangat Tinggi")))) -> — | J28: =IF(F28="","—",IF(F28<9,"🔴 Rendah",IF(F28<=13,"🟡 Sedang",IF(F28<=17,"🟢 Tinggi","🔵 Sangat Tinggi")))) -> — | K28: =IF(G28="","—",IF(G28<9,"🔴 Rendah",IF(G28<=13,"🟡 Sedang",IF(G28<=17,"🟢 Tinggi","🔵 Sangat Tinggi")))) -> —
A29: 18 | H29: =IF(D29="","—",IF(D29<9,"🔴 Rendah",IF(D29<=13,"🟡 Sedang",IF(D29<=17,"🟢 Tinggi","🔵 Sangat Tinggi")))) -> — | I29: =IF(E29="","—",IF(E29<9,"🔴 Rendah",IF(E29<=13,"🟡 Sedang",IF(E29<=17,"🟢 Tinggi","🔵 Sangat Tinggi")))) -> — | J29: =IF(F29="","—",IF(F29<9,"🔴 Rendah",IF(F29<=13,"🟡 Sedang",IF(F29<=17,"🟢 Tinggi","🔵 Sangat Tinggi")))) -> — | K29: =IF(G29="","—",IF(G29<9,"🔴 Rendah",IF(G29<=13,"🟡 Sedang",IF(G29<=17,"🟢 Tinggi","🔵 Sangat Tinggi")))) -> —
A30: 19 | H30: =IF(D30="","—",IF(D30<9,"🔴 Rendah",IF(D30<=13,"🟡 Sedang",IF(D30<=17,"🟢 Tinggi","🔵 Sangat Tinggi")))) -> — | I30: =IF(E30="","—",IF(E30<9,"🔴 Rendah",IF(E30<=13,"🟡 Sedang",IF(E30<=17,"🟢 Tinggi","🔵 Sangat Tinggi")))) -> — | J30: =IF(F30="","—",IF(F30<9,"🔴 Rendah",IF(F30<=13,"🟡 Sedang",IF(F30<=17,"🟢 Tinggi","🔵 Sangat Tinggi")))) -> — | K30: =IF(G30="","—",IF(G30<9,"🔴 Rendah",IF(G30<=13,"🟡 Sedang",IF(G30<=17,"🟢 Tinggi","🔵 Sangat Tinggi")))) -> —
A31: 20 | H31: =IF(D31="","—",IF(D31<9,"🔴 Rendah",IF(D31<=13,"🟡 Sedang",IF(D31<=17,"🟢 Tinggi","🔵 Sangat Tinggi")))) -> — | I31: =IF(E31="","—",IF(E31<9,"🔴 Rendah",IF(E31<=13,"🟡 Sedang",IF(E31<=17,"🟢 Tinggi","🔵 Sangat Tinggi")))) -> — | J31: =IF(F31="","—",IF(F31<9,"🔴 Rendah",IF(F31<=13,"🟡 Sedang",IF(F31<=17,"🟢 Tinggi","🔵 Sangat Tinggi")))) -> — | K31: =IF(G31="","—",IF(G31<9,"🔴 Rendah",IF(G31<=13,"🟡 Sedang",IF(G31<=17,"🟢 Tinggi","🔵 Sangat Tinggi")))) -> —
A32: 21 | H32: =IF(D32="","—",IF(D32<9,"🔴 Rendah",IF(D32<=13,"🟡 Sedang",IF(D32<=17,"🟢 Tinggi","🔵 Sangat Tinggi")))) -> — | I32: =IF(E32="","—",IF(E32<9,"🔴 Rendah",IF(E32<=13,"🟡 Sedang",IF(E32<=17,"🟢 Tinggi","🔵 Sangat Tinggi")))) -> — | J32: =IF(F32="","—",IF(F32<9,"🔴 Rendah",IF(F32<=13,"🟡 Sedang",IF(F32<=17,"🟢 Tinggi","🔵 Sangat Tinggi")))) -> — | K32: =IF(G32="","—",IF(G32<9,"🔴 Rendah",IF(G32<=13,"🟡 Sedang",IF(G32<=17,"🟢 Tinggi","🔵 Sangat Tinggi")))) -> —
A33: 22 | H33: =IF(D33="","—",IF(D33<9,"🔴 Rendah",IF(D33<=13,"🟡 Sedang",IF(D33<=17,"🟢 Tinggi","🔵 Sangat Tinggi")))) -> — | I33: =IF(E33="","—",IF(E33<9,"🔴 Rendah",IF(E33<=13,"🟡 Sedang",IF(E33<=17,"🟢 Tinggi","🔵 Sangat Tinggi")))) -> — | J33: =IF(F33="","—",IF(F33<9,"🔴 Rendah",IF(F33<=13,"🟡 Sedang",IF(F33<=17,"🟢 Tinggi","🔵 Sangat Tinggi")))) -> — | K33: =IF(G33="","—",IF(G33<9,"🔴 Rendah",IF(G33<=13,"🟡 Sedang",IF(G33<=17,"🟢 Tinggi","🔵 Sangat Tinggi")))) -> —
A34: 23 | H34: =IF(D34="","—",IF(D34<9,"🔴 Rendah",IF(D34<=13,"🟡 Sedang",IF(D34<=17,"🟢 Tinggi","🔵 Sangat Tinggi")))) -> — | I34: =IF(E34="","—",IF(E34<9,"🔴 Rendah",IF(E34<=13,"🟡 Sedang",IF(E34<=17,"🟢 Tinggi","🔵 Sangat Tinggi")))) -> — | J34: =IF(F34="","—",IF(F34<9,"🔴 Rendah",IF(F34<=13,"🟡 Sedang",IF(F34<=17,"🟢 Tinggi","🔵 Sangat Tinggi")))) -> — | K34: =IF(G34="","—",IF(G34<9,"🔴 Rendah",IF(G34<=13,"🟡 Sedang",IF(G34<=17,"🟢 Tinggi","🔵 Sangat Tinggi")))) -> —
... A41: 30 | H41: =IF(D41="","—",IF(D41<9,"🔴 Rendah",IF(D41<=13,"🟡 Sedang",IF(D41<=17,"🟢 Tinggi","🔵 Sangat Tinggi")))) -> — | I41: =IF(E41="","—",IF(E41<9,"🔴 Rendah",IF(E41<=13,"🟡 Sedang",IF(E41<=17,"🟢 Tinggi","🔵 Sangat Tinggi")))) -> — | J41: =IF(F41="","—",IF(F41<9,"🔴 Rendah",IF(F41<=13,"🟡 Sedang",IF(F41<=17,"🟢 Tinggi","🔵 Sangat Tinggi")))) -> — | K41: =IF(G41="","—",IF(G41<9,"🔴 Rendah",IF(G41<=13,"🟡 Sedang",IF(G41<=17,"🟢 Tinggi","🔵 Sangat Tinggi")))) -> —
A43: ↓ Setelah mengisi skor di atas, lanjut ke sheet berikutnya untuk melihat analisa kesesuaian posisi per kandidat

Sheet 📊 Analisa Batch Kandidat
A1: ANALISA BATCH KANDIDAT — KESESUAIAN POSISI EASY LEGAL
A2: Skor ditarik otomatis dari sheet '📥 Input Skor GForm' | Cocok posisi mana? Berapa % fit-nya?
A4: LOGIKA KESESUAIAN POSISI (Rumus Fit Score)
A5: Legal Officer (LO) | C5: C SANGAT TINGGI / TINGGI + D SEDANG ke atas = Fit tinggi
A6: Customer Care / CRM | C6: S TINGGI / SANGAT TINGGI + I TINGGI = Fit tinggi
A7: PLA (Pre-Closing Lead) | C7: D TINGGI / SANGAT TINGGI + I TINGGI = Fit tinggi
A8: Marketing | C8: I SANGAT TINGGI + D TINGGI + C RENDAH = Fit tinggi
A10: No | B10: Nama Kandidat | C10: Posisi Dilamar | D10: D | E10: S | F10: C | G10: I | H10: Fit LO (%) | I10: Fit CRM (%) | J10: Fit PLA (%) | K10: Fit Mkt (%) | L10: ✅ REKOMENDASI POSISI
A11: 1 | B11: ='📥 Input Skor GForm'!B12 -> Tiara Nabila | C11: ='📥 Input Skor GForm'!C12 -> Easy Legal | D11: ='📥 Input Skor GForm'!D12 -> 7 | E11: ='📥 Input Skor GForm'!E12 -> 20 | F11: ='📥 Input Skor GForm'!F12 -> 8 | G11: ='📥 Input Skor GForm'!G12 -> 6 | H11: =IF(OR(D11="",F11=""),"—",MIN(100, IF(F11>=18,50,IF(F11>=14,38,IF(F11>=9,20,5))) + IF(D11>=14,28,IF(D11>=9,18,8)) + IF(G11<9,12,IF(G11<=13,6,0)) + IF(E11<9,10,IF(E11<=13,5,0)))) -> 25 | I11: =IF(OR(E11="",G11=""),"—",MIN(100, IF(E11>=18,48,IF(E11>=14,36,IF(E11>=9,20,5))) + IF(G11>=14,28,IF(G11>=9,18,8)) + IF(D11<9,12,IF(D11<=13,6,0)) + IF(F11<=13,12,IF(F11<=17,6,0)))) -> 80 | J11: =IF(OR(D11="",G11=""),"—",MIN(100, IF(D11>=18,48,IF(D11>=14,36,IF(D11>=9,20,5))) + IF(G11>=14,30,IF(G11>=9,18,8)) + IF(E11<9,12,IF(E11<=13,6,0)) + IF(F11<=13,10,IF(F11<=17,5,0)))) -> 23 | K11: =IF(OR(G11="",D11=""),"—",MIN(100, IF(G11>=18,50,IF(G11>=14,38,IF(G11>=9,20,5))) + IF(D11>=14,28,IF(D11>=9,18,8)) + IF(F11<9,12,IF(F11<=13,6,0)) + IF(E11<9,10,IF(E11<=13,5,0)))) -> 25 | L11: =IF(OR(H11="—",I11="—"),"Isi skor dulu",IF(MAX(H11,I11,J11,K11)=H11,"⚖️ Legal Officer",IF(MAX(H11,I11,J11,K11)=I11,"🎧 Customer Care/CRM",IF(MAX(H11,I11,J11,K11)=J11,"🎯 PLA Closing","📣 Marketing")))) -> 🎧 Customer Care/CRM
A12: 2 | B12: ='📥 Input Skor GForm'!B13 -> Amnila Hanisah Rifainy | C12: ='📥 Input Skor GForm'!C13 -> Easy Legal | D12: ='📥 Input Skor GForm'!D13 -> 3 | E12: ='📥 Input Skor GForm'!E13 -> 20 | F12: ='📥 Input Skor GForm'!F13 -> 14 | G12: ='📥 Input Skor GForm'!G13 -> 7 | H12: =IF(OR(D12="",F12=""),"—",MIN(100, IF(F12>=18,50,IF(F12>=14,38,IF(F12>=9,20,5))) + IF(D12>=14,28,IF(D12>=9,18,8)) + IF(G12<9,12,IF(G12<=13,6,0)) + IF(E12<9,10,IF(E12<=13,5,0)))) -> 58 | I12: =IF(OR(E12="",G12=""),"—",MIN(100, IF(E12>=18,48,IF(E12>=14,36,IF(E12>=9,20,5))) + IF(G12>=14,28,IF(G12>=9,18,8)) + IF(D12<9,12,IF(D12<=13,6,0)) + IF(F12<=13,12,IF(F12<=17,6,0)))) -> 74 | J12: =IF(OR(D12="",G12=""),"—",MIN(100, IF(D12>=18,48,IF(D12>=14,36,IF(D12>=9,20,5))) + IF(G12>=14,30,IF(G12>=9,18,8)) + IF(E12<9,12,IF(E12<=13,6,0)) + IF(F12<=13,10,IF(F12<=17,5,0)))) -> 18 | K12: =IF(OR(G12="",D12=""),"—",MIN(100, IF(G12>=18,50,IF(G12>=14,38,IF(G12>=9,20,5))) + IF(D12>=14,28,IF(D12>=9,18,8)) + IF(F12<9,12,IF(F12<=13,6,0)) + IF(E12<9,10,IF(E12<=13,5,0)))) -> 13 | L12: =IF(OR(H12="—",I12="—"),"Isi skor dulu",IF(MAX(H12,I12,J12,K12)=H12,"⚖️ Legal Officer",IF(MAX(H12,I12,J12,K12)=I12,"🎧 Customer Care/CRM",IF(MAX(H12,I12,J12,K12)=J12,"🎯 PLA Closing","📣 Marketing")))) -> 🎧 Customer Care/CRM
A13: 3 | B13: ='📥 Input Skor GForm'!B14 -> Fika Nur Fatmala | C13: ='📥 Input Skor GForm'!C14 -> Easy Legal | D13: ='📥 Input Skor GForm'!D14 -> 4 | E13: ='📥 Input Skor GForm'!E14 -> 16 | F13: ='📥 Input Skor GForm'!F14 -> 14 | G13: ='📥 Input Skor GForm'!G14 -> 8 | H13: =IF(OR(D13="",F13=""),"—",MIN(100, IF(F13>=18,50,IF(F13>=14,38,IF(F13>=9,20,5))) + IF(D13>=14,28,IF(D13>=9,18,8)) + IF(G13<9,12,IF(G13<=13,6,0)) + IF(E13<9,10,IF(E13<=13,5,0)))) -> 58 | I13: =IF(OR(E13="",G13=""),"—",MIN(100, IF(E13>=18,48,IF(E13>=14,36,IF(E13>=9,20,5))) + IF(G13>=14,28,IF(G13>=9,18,8)) + IF(D13<9,12,IF(D13<=13,6,0)) + IF(F13<=13,12,IF(F13<=17,6,0)))) -> 62 | J13: =IF(OR(D13="",G13=""),"—",MIN(100, IF(D13>=18,48,IF(D13>=14,36,IF(D13>=9,20,5))) + IF(G13>=14,30,IF(G13>=9,18,8)) + IF(E13<9,12,IF(E13<=13,6,0)) + IF(F13<=13,10,IF(F13<=17,5,0)))) -> 18 | K13: =IF(OR(G13="",D13=""),"—",MIN(100, IF(G13>=18,50,IF(G13>=14,38,IF(G13>=9,20,5))) + IF(D13>=14,28,IF(D13>=9,18,8)) + IF(F13<9,12,IF(F13<=13,6,0)) + IF(E13<9,10,IF(E13<=13,5,0)))) -> 13 | L13: =IF(OR(H13="—",I13="—"),"Isi skor dulu",IF(MAX(H13,I13,J13,K13)=H13,"⚖️ Legal Officer",IF(MAX(H13,I13,J13,K13)=I13,"🎧 Customer Care/CRM",IF(MAX(H13,I13,J13,K13)=J13,"🎯 PLA Closing","📣 Marketing")))) -> 🎧 Customer Care/CRM
A14: 4 | B14: ='📥 Input Skor GForm'!B15 -> Fauzia Rahmawati | C14: ='📥 Input Skor GForm'!C15 -> Easy Legal | D14: ='📥 Input Skor GForm'!D15 -> 3 | E14: ='📥 Input Skor GForm'!E15 -> 16 | F14: ='📥 Input Skor GForm'!F15 -> 12 | G14: ='📥 Input Skor GForm'!G15 -> 10 | H14: =IF(OR(D14="",F14=""),"—",MIN(100, IF(F14>=18,50,IF(F14>=14,38,IF(F14>=9,20,5))) + IF(D14>=14,28,IF(D14>=9,18,8)) + IF(G14<9,12,IF(G14<=13,6,0)) + IF(E14<9,10,IF(E14<=13,5,0)))) -> 34 | I14: =IF(OR(E14="",G14=""),"—",MIN(100, IF(E14>=18,48,IF(E14>=14,36,IF(E14>=9,20,5))) + IF(G14>=14,28,IF(G14>=9,18,8)) + IF(D14<9,12,IF(D14<=13,6,0)) + IF(F14<=13,12,IF(F14<=17,6,0)))) -> 78 | J14: =IF(OR(D14="",G14=""),"—",MIN(100, IF(D14>=18,48,IF(D14>=14,36,IF(D14>=9,20,5))) + IF(G14>=14,30,IF(G14>=9,18,8)) + IF(E14<9,12,IF(E14<=13,6,0)) + IF(F14<=13,10,IF(F14<=17,5,0)))) -> 33 | K14: =IF(OR(G14="",D14=""),"—",MIN(100, IF(G14>=18,50,IF(G14>=14,38,IF(G14>=9,20,5))) + IF(D14>=14,28,IF(D14>=9,18,8)) + IF(F14<9,12,IF(F14<=13,6,0)) + IF(E14<9,10,IF(E14<=13,5,0)))) -> 34 | L14: =IF(OR(H14="—",I14="—"),"Isi skor dulu",IF(MAX(H14,I14,J14,K14)=H14,"⚖️ Legal Officer",IF(MAX(H14,I14,J14,K14)=I14,"🎧 Customer Care/CRM",IF(MAX(H14,I14,J14,K14)=J14,"🎯 PLA Closing","📣 Marketing")))) -> 🎧 Customer Care/CRM
A15: 5 | B15: ='📥 Input Skor GForm'!B16 -> SALMAN ARYANA | C15: ='📥 Input Skor GForm'!C16 -> Easy Legal | D15: ='📥 Input Skor GForm'!D16 -> 10 | E15: ='📥 Input Skor GForm'!E16 -> 15 | F15: ='📥 Input Skor GForm'!F16 -> 12 | G15: ='📥 Input Skor GForm'!G16 -> 4 | H15: =IF(OR(D15="",F15=""),"—",MIN(100, IF(F15>=18,50,IF(F15>=14,38,IF(F15>=9,20,5))) + IF(D15>=14,28,IF(D15>=9,18,8)) + IF(G15<9,12,IF(G15<=13,6,0)) + IF(E15<9,10,IF(E15<=13,5,0)))) -> 50 | I15: =IF(OR(E15="",G15=""),"—",MIN(100, IF(E15>=18,48,IF(E15>=14,36,IF(E15>=9,20,5))) + IF(G15>=14,28,IF(G15>=9,18,8)) + IF(D15<9,12,IF(D15<=13,6,0)) + IF(F15<=13,12,IF(F15<=17,6,0)))) -> 62 | J15: =IF(OR(D15="",G15=""),"—",MIN(100, IF(D15>=18,48,IF(D15>=14,36,IF(D15>=9,20,5))) + IF(G15>=14,30,IF(G15>=9,18,8)) + IF(E15<9,12,IF(E15<=13,6,0)) + IF(F15<=13,10,IF(F15<=17,5,0)))) -> 38 | K15: =IF(OR(G15="",D15=""),"—",MIN(100, IF(G15>=18,50,IF(G15>=14,38,IF(G15>=9,20,5))) + IF(D15>=14,28,IF(D15>=9,18,8)) + IF(F15<9,12,IF(F15<=13,6,0)) + IF(E15<9,10,IF(E15<=13,5,0)))) -> 29 | L15: =IF(OR(H15="—",I15="—"),"Isi skor dulu",IF(MAX(H15,I15,J15,K15)=H15,"⚖️ Legal Officer",IF(MAX(H15,I15,J15,K15)=I15,"🎧 Customer Care/CRM",IF(MAX(H15,I15,J15,K15)=J15,"🎯 PLA Closing","📣 Marketing")))) -> 🎧 Customer Care/CRM
A16: 6 | B16: ='📥 Input Skor GForm'!B17 -> Wulan Eka Refiana | C16: ='📥 Input Skor GForm'!C17 -> Easy Legal | D16: ='📥 Input Skor GForm'!D17 -> 6 | E16: ='📥 Input Skor GForm'!E17 -> 15 | F16: ='📥 Input Skor GForm'!F17 -> 16 | G16: ='📥 Input Skor GForm'!G17 -> 4 | H16: =IF(OR(D16="",F16=""),"—",MIN(100, IF(F16>=18,50,IF(F16>=14,38,IF(F16>=9,20,5))) + IF(D16>=14,28,IF(D16>=9,18,8)) + IF(G16<9,12,IF(G16<=13,6,0)) + IF(E16<9,10,IF(E16<=13,5,0)))) -> 58 | I16: =IF(OR(E16="",G16=""),"—",MIN(100, IF(E16>=18,48,IF(E16>=14,36,IF(E16>=9,20,5))) + IF(G16>=14,28,IF(G16>=9,18,8)) + IF(D16<9,12,IF(D16<=13,6,0)) + IF(F16<=13,12,IF(F16<=17,6,0)))) -> 62 | J16: =IF(OR(D16="",G16=""),"—",MIN(100, IF(D16>=18,48,IF(D16>=14,36,IF(D16>=9,20,5))) + IF(G16>=14,30,IF(G16>=9,18,8)) + IF(E16<9,12,IF(E16<=13,6,0)) + IF(F16<=13,10,IF(F16<=17,5,0)))) -> 18 | K16: =IF(OR(G16="",D16=""),"—",MIN(100, IF(G16>=18,50,IF(G16>=14,38,IF(G16>=9,20,5))) + IF(D16>=14,28,IF(D16>=9,18,8)) + IF(F16<9,12,IF(F16<=13,6,0)) + IF(E16<9,10,IF(E16<=13,5,0)))) -> 13 | L16: =IF(OR(H16="—",I16="—"),"Isi skor dulu",IF(MAX(H16,I16,J16,K16)=H16,"⚖️ Legal Officer",IF(MAX(H16,I16,J16,K16)=I16,"🎧 Customer Care/CRM",IF(MAX(H16,I16,J16,K16)=J16,"🎯 PLA Closing","📣 Marketing")))) -> 🎧 Customer Care/CRM
A17: 7 | B17: ='📥 Input Skor GForm'!B18 -> Mulyanasari (Riri) | C17: ='📥 Input Skor GForm'!C18 -> Easy Legal | D17: ='📥 Input Skor GForm'!D18 -> 4 | E17: ='📥 Input Skor GForm'!E18 -> 15 | F17: ='📥 Input Skor GForm'!F18 -> 16 | G17: ='📥 Input Skor GForm'!G18 -> 6 | H17: =IF(OR(D17="",F17=""),"—",MIN(100, IF(F17>=18,50,IF(F17>=14,38,IF(F17>=9,20,5))) + IF(D17>=14,28,IF(D17>=9,18,8)) + IF(G17<9,12,IF(G17<=13,6,0)) + IF(E17<9,10,IF(E17<=13,5,0)))) -> 58 | I17: =IF(OR(E17="",G17=""),"—",MIN(100, IF(E17>=18,48,IF(E17>=14,36,IF(E17>=9,20,5))) + IF(G17>=14,28,IF(G17>=9,18,8)) + IF(D17<9,12,IF(D17<=13,6,0)) + IF(F17<=13,12,IF(F17<=17,6,0)))) -> 62 | J17: =IF(OR(D17="",G17=""),"—",MIN(100, IF(D17>=18,48,IF(D17>=14,36,IF(D17>=9,20,5))) + IF(G17>=14,30,IF(G17>=9,18,8)) + IF(E17<9,12,IF(E17<=13,6,0)) + IF(F17<=13,10,IF(F17<=17,5,0)))) -> 18 | K17: =IF(OR(G17="",D17=""),"—",MIN(100, IF(G17>=18,50,IF(G17>=14,38,IF(G17>=9,20,5))) + IF(D17>=14,28,IF(D17>=9,18,8)) + IF(F17<9,12,IF(F17<=13,6,0)) + IF(E17<9,10,IF(E17<=13,5,0)))) -> 13 | L17: =IF(OR(H17="—",I17="—"),"Isi skor dulu",IF(MAX(H17,I17,J17,K17)=H17,"⚖️ Legal Officer",IF(MAX(H17,I17,J17,K17)=I17,"🎧 Customer Care/CRM",IF(MAX(H17,I17,J17,K17)=J17,"🎯 PLA Closing","📣 Marketing")))) -> 🎧 Customer Care/CRM
A18: 8 | B18: ='📥 Input Skor GForm'!B19 -> yumita | C18: ='📥 Input Skor GForm'!C19 -> Easy Legal | D18: ='📥 Input Skor GForm'!D19 -> 7 | E18: ='📥 Input Skor GForm'!E19 -> 14 | F18: ='📥 Input Skor GForm'!F19 -> 11 | G18: ='📥 Input Skor GForm'!G19 -> 9 | H18: =IF(OR(D18="",F18=""),"—",MIN(100, IF(F18>=18,50,IF(F18>=14,38,IF(F18>=9,20,5))) + IF(D18>=14,28,IF(D18>=9,18,8)) + IF(G18<9,12,IF(G18<=13,6,0)) + IF(E18<9,10,IF(E18<=13,5,0)))) -> 34 | I18: =IF(OR(E18="",G18=""),"—",MIN(100, IF(E18>=18,48,IF(E18>=14,36,IF(E18>=9,20,5))) + IF(G18>=14,28,IF(G18>=9,18,8)) + IF(D18<9,12,IF(D18<=13,6,0)) + IF(F18<=13,12,IF(F18<=17,6,0)))) -> 78 | J18: =IF(OR(D18="",G18=""),"—",MIN(100, IF(D18>=18,48,IF(D18>=14,36,IF(D18>=9,20,5))) + IF(G18>=14,30,IF(G18>=9,18,8)) + IF(E18<9,12,IF(E18<=13,6,0)) + IF(F18<=13,10,IF(F18<=17,5,0)))) -> 33 | K18: =IF(OR(G18="",D18=""),"—",MIN(100, IF(G18>=18,50,IF(G18>=14,38,IF(G18>=9,20,5))) + IF(D18>=14,28,IF(D18>=9,18,8)) + IF(F18<9,12,IF(F18<=13,6,0)) + IF(E18<9,10,IF(E18<=13,5,0)))) -> 34 | L18: =IF(OR(H18="—",I18="—"),"Isi skor dulu",IF(MAX(H18,I18,J18,K18)=H18,"⚖️ Legal Officer",IF(MAX(H18,I18,J18,K18)=I18,"🎧 Customer Care/CRM",IF(MAX(H18,I18,J18,K18)=J18,"🎯 PLA Closing","📣 Marketing")))) -> 🎧 Customer Care/CRM
A19: 9 | B19: ='📥 Input Skor GForm'!B20 -> Ela Yuniar | C19: ='📥 Input Skor GForm'!C20 -> Easy Legal | D19: ='📥 Input Skor GForm'!D20 -> 3 | E19: ='📥 Input Skor GForm'!E20 -> 14 | F19: ='📥 Input Skor GForm'!F20 -> 15 | G19: ='📥 Input Skor GForm'!G20 -> 9 | H19: =IF(OR(D19="",F19=""),"—",MIN(100, IF(F19>=18,50,IF(F19>=14,38,IF(F19>=9,20,5))) + IF(D19>=14,28,IF(D19>=9,18,8)) + IF(G19<9,12,IF(G19<=13,6,0)) + IF(E19<9,10,IF(E19<=13,5,0)))) -> 52 | I19: =IF(OR(E19="",G19=""),"—",MIN(100, IF(E19>=18,48,IF(E19>=14,36,IF(E19>=9,20,5))) + IF(G19>=14,28,IF(G19>=9,18,8)) + IF(D19<9,12,IF(D19<=13,6,0)) + IF(F19<=13,12,IF(F19<=17,6,0)))) -> 72 | J19: =IF(OR(D19="",G19=""),"—",MIN(100, IF(D19>=18,48,IF(D19>=14,36,IF(D19>=9,20,5))) + IF(G19>=14,30,IF(G19>=9,18,8)) + IF(E19<9,12,IF(E19<=13,6,0)) + IF(F19<=13,10,IF(F19<=17,5,0)))) -> 28 | K19: =IF(OR(G19="",D19=""),"—",MIN(100, IF(G19>=18,50,IF(G19>=14,38,IF(G19>=9,20,5))) + IF(D19>=14,28,IF(D19>=9,18,8)) + IF(F19<9,12,IF(F19<=13,6,0)) + IF(E19<9,10,IF(E19<=13,5,0)))) -> 28 | L19: =IF(OR(H19="—",I19="—"),"Isi skor dulu",IF(MAX(H19,I19,J19,K19)=H19,"⚖️ Legal Officer",IF(MAX(H19,I19,J19,K19)=I19,"🎧 Customer Care/CRM",IF(MAX(H19,I19,J19,K19)=J19,"🎯 PLA Closing","📣 Marketing")))) -> 🎧 Customer Care/CRM
A20: 10 | B20: ='📥 Input Skor GForm'!B21 -> yunia raventi | C20: ='📥 Input Skor GForm'!C21 -> Easy Legal | D20: ='📥 Input Skor GForm'!D21 -> 3 | E20: ='📥 Input Skor GForm'!E21 -> 14 | F20: ='📥 Input Skor GForm'!F21 -> 15 | G20: ='📥 Input Skor GForm'!G21 -> 9 | H20: =IF(OR(D20="",F20=""),"—",MIN(100, IF(F20>=18,50,IF(F20>=14,38,IF(F20>=9,20,5))) + IF(D20>=14,28,IF(D20>=9,18,8)) + IF(G20<9,12,IF(G20<=13,6,0)) + IF(E20<9,10,IF(E20<=13,5,0)))) -> 52 | I20: =IF(OR(E20="",G20=""),"—",MIN(100, IF(E20>=18,48,IF(E20>=14,36,IF(E20>=9,20,5))) + IF(G20>=14,28,IF(G20>=9,18,8)) + IF(D20<9,12,IF(D20<=13,6,0)) + IF(F20<=13,12,IF(F20<=17,6,0)))) -> 72 | J20: =IF(OR(D20="",G20=""),"—",MIN(100, IF(D20>=18,48,IF(D20>=14,36,IF(D20>=9,20,5))) + IF(G20>=14,30,IF(G20>=9,18,8)) + IF(E20<9,12,IF(E20<=13,6,0)) + IF(F20<=13,10,IF(F20<=17,5,0)))) -> 28 | K20: =IF(OR(G20="",D20=""),"—",MIN(100, IF(G20>=18,50,IF(G20>=14,38,IF(G20>=9,20,5))) + IF(D20>=14,28,IF(D20>=9,18,8)) + IF(F20<9,12,IF(F20<=13,6,0)) + IF(E20<9,10,IF(E20<=13,5,0)))) -> 28 | L20: =IF(OR(H20="—",I20="—"),"Isi skor dulu",IF(MAX(H20,I20,J20,K20)=H20,"⚖️ Legal Officer",IF(MAX(H20,I20,J20,K20)=I20,"🎧 Customer Care/CRM",IF(MAX(H20,I20,J20,K20)=J20,"🎯 PLA Closing","📣 Marketing")))) -> 🎧 Customer Care/CRM
A21: 11 | B21: ='📥 Input Skor GForm'!B22 -> AULIA AZMI IZZATUL HAQ | C21: ='📥 Input Skor GForm'!C22 -> Easy Legal | D21: ='📥 Input Skor GForm'!D22 -> 4 | E21: ='📥 Input Skor GForm'!E22 -> 13 | F21: ='📥 Input Skor GForm'!F22 -> 21 | G21: ='📥 Input Skor GForm'!G22 -> 3 | H21: =IF(OR(D21="",F21=""),"—",MIN(100, IF(F21>=18,50,IF(F21>=14,38,IF(F21>=9,20,5))) + IF(D21>=14,28,IF(D21>=9,18,8)) + IF(G21<9,12,IF(G21<=13,6,0)) + IF(E21<9,10,IF(E21<=13,5,0)))) -> 75 | I21: =IF(OR(E21="",G21=""),"—",MIN(100, IF(E21>=18,48,IF(E21>=14,36,IF(E21>=9,20,5))) + IF(G21>=14,28,IF(G21>=9,18,8)) + IF(D21<9,12,IF(D21<=13,6,0)) + IF(F21<=13,12,IF(F21<=17,6,0)))) -> 40 | J21: =IF(OR(D21="",G21=""),"—",MIN(100, IF(D21>=18,48,IF(D21>=14,36,IF(D21>=9,20,5))) + IF(G21>=14,30,IF(G21>=9,18,8)) + IF(E21<9,12,IF(E21<=13,6,0)) + IF(F21<=13,10,IF(F21<=17,5,0)))) -> 19 | K21: =IF(OR(G21="",D21=""),"—",MIN(100, IF(G21>=18,50,IF(G21>=14,38,IF(G21>=9,20,5))) + IF(D21>=14,28,IF(D21>=9,18,8)) + IF(F21<9,12,IF(F21<=13,6,0)) + IF(E21<9,10,IF(E21<=13,5,0)))) -> 18 | L21: =IF(OR(H21="—",I21="—"),"Isi skor dulu",IF(MAX(H21,I21,J21,K21)=H21,"⚖️ Legal Officer",IF(MAX(H21,I21,J21,K21)=I21,"🎧 Customer Care/CRM",IF(MAX(H21,I21,J21,K21)=J21,"🎯 PLA Closing","📣 Marketing")))) -> ⚖️ Legal Officer
A22: 12 | B22: ='📥 Input Skor GForm'!B23 -> 0 | C22: ='📥 Input Skor GForm'!C23 -> 0 | D22: ='📥 Input Skor GForm'!D23 -> 0 | E22: ='📥 Input Skor GForm'!E23 -> 0 | F22: ='📥 Input Skor GForm'!F23 -> 0 | G22: ='📥 Input Skor GForm'!G23 -> 0 | H22: =IF(OR(D22="",F22=""),"—",MIN(100, IF(F22>=18,50,IF(F22>=14,38,IF(F22>=9,20,5))) + IF(D22>=14,28,IF(D22>=9,18,8)) + IF(G22<9,12,IF(G22<=13,6,0)) + IF(E22<9,10,IF(E22<=13,5,0)))) -> — | I22: =IF(OR(E22="",G22=""),"—",MIN(100, IF(E22>=18,48,IF(E22>=14,36,IF(E22>=9,20,5))) + IF(G22>=14,28,IF(G22>=9,18,8)) + IF(D22<9,12,IF(D22<=13,6,0)) + IF(F22<=13,12,IF(F22<=17,6,0)))) -> — | J22: =IF(OR(D22="",G22=""),"—",MIN(100, IF(D22>=18,48,IF(D22>=14,36,IF(D22>=9,20,5))) + IF(G22>=14,30,IF(G22>=9,18,8)) + IF(E22<9,12,IF(E22<=13,6,0)) + IF(F22<=13,10,IF(F22<=17,5,0)))) -> — | K22: =IF(OR(G22="",D22=""),"—",MIN(100, IF(G22>=18,50,IF(G22>=14,38,IF(G22>=9,20,5))) + IF(D22>=14,28,IF(D22>=9,18,8)) + IF(F22<9,12,IF(F22<=13,6,0)) + IF(E22<9,10,IF(E22<=13,5,0)))) -> — | L22: =IF(OR(H22="—",I22="—"),"Isi skor dulu",IF(MAX(H22,I22,J22,K22)=H22,"⚖️ Legal Officer",IF(MAX(H22,I22,J22,K22)=I22,"🎧 Customer Care/CRM",IF(MAX(H22,I22,J22,K22)=J22,"🎯 PLA Closing","📣 Marketing")))) -> Isi skor dulu
... A40: 30 | B40: ='📥 Input Skor GForm'!B41 -> 0 | C40: ='📥 Input Skor GForm'!C41 -> 0 | D40: ='📥 Input Skor GForm'!D41 -> 0 | E40: ='📥 Input Skor GForm'!E41 -> 0 | F40: ='📥 Input Skor GForm'!F41 -> 0 | G40: ='📥 Input Skor GForm'!G41 -> 0 | H40: =IF(OR(D40="",F40=""),"—",MIN(100, IF(F40>=18,50,IF(F40>=14,38,IF(F40>=9,20,5))) + IF(D40>=14,28,IF(D40>=9,18,8)) + IF(G40<9,12,IF(G40<=13,6,0)) + IF(E40<9,10,IF(E40<=13,5,0)))) -> — | I40: =IF(OR(E40="",G40=""),"—",MIN(100, IF(E40>=18,48,IF(E40>=14,36,IF(E40>=9,20,5))) + IF(G40>=14,28,IF(G40>=9,18,8)) + IF(D40<9,12,IF(D40<=13,6,0)) + IF(F40<=13,12,IF(F40<=17,6,0)))) -> — | J40: =IF(OR(D40="",G40=""),"—",MIN(100, IF(D40>=18,48,IF(D40>=14,36,IF(D40>=9,20,5))) + IF(G40>=14,30,IF(G40>=9,18,8)) + IF(E40<9,12,IF(E40<=13,6,0)) + IF(F40<=13,10,IF(F40<=17,5,0)))) -> — | K40: =IF(OR(G40="",D40=""),"—",MIN(100, IF(G40>=18,50,IF(G40>=14,38,IF(G40>=9,20,5))) + IF(D40>=14,28,IF(D40>=9,18,8)) + IF(F40<9,12,IF(F40<=13,6,0)) + IF(E40<9,10,IF(E40<=13,5,0)))) -> — | L40: =IF(OR(H40="—",I40="—"),"Isi skor dulu",IF(MAX(H40,I40,J40,K40)=H40,"⚖️ Legal Officer",IF(MAX(H40,I40,J40,K40)=I40,"🎧 Customer Care/CRM",IF(MAX(H40,I40,J40,K40)=J40,"🎯 PLA Closing","📣 Marketing")))) -> Isi skor dulu

Sheet 📖 Interpretasi Skor
B1: PANDUAN INTERPRETASI SKOR DISC — PER DIMENSI & LEVEL
B2: Easy Legal | Threshold: <9 Rendah | 9-13 Sedang | 14-17 Tinggi | ≥18 Sangat Tinggi
B4: D — DOMINANCE — Cara merespons tantangan & masalah
B5: Level | C5: Range | D5: Interpretasi & Implikasi Rekrutmen
B6: Rendah | C6: < 9 | D6: Menghindari konflik, tidak agresif, lebih suka dibimbing. Kurang cocok PLA.
B7: Sedang | C7: 9–13 | D7: Bisa tegas bila diperlukan, namun tidak dominan. Cocok sebagai support role.
B8: Tinggi | C8: 14–17 | D8: Tegas, mandiri, berorientasi hasil. Cocok CRM supervisor, LO senior, PLA.
B9: Sgt Tinggi | C9: ≥18 | D9: Sangat dominan, kompetitif, risk taker. Sangat cocok PLA & team lead.
B11: S — STEADINESS — Cara merespons ritme & lingkungan kerja
B12: Level | C12: Range | D12: Interpretasi & Implikasi Rekrutmen
B13: Rendah | C13: < 9 | D13: Mudah bosan, suka perubahan cepat, kurang sabar. Kurang cocok CRM panjang.
B14: Sedang | C14: 9–13 | D14: Cukup stabil, bisa adaptasi. Cocok hampir semua posisi dengan supervisi.
B15: Tinggi | C15: 14–17 | D15: Sabar, loyal, konsisten. Sangat cocok CRM (handle komplain), LO (repetitive doc).
B16: Sgt Tinggi | C16: ≥18 | D16: Sangat sabar & stabil. Ideal CRM, namun perlu dorongan untuk PLA/Marketing.
B18: C — CONSCIENTIOUSNESS — Cara merespons aturan & standar
B19: Level | C19: Range | D19: Interpretasi & Implikasi Rekrutmen
B20: Rendah | C20: < 9 | D20: Fleksibel, kurang sistematis. Cocok Marketing kreatif, tidak cocok LO.
B21: Sedang | C21: 9–13 | D21: Cukup teliti, bisa mengikuti SOP. Bisa LO entry-level dengan training.
B22: Tinggi | C22: 14–17 | D22: Akurat, sistematis, berbasis data. Sangat cocok Legal Officer.
B23: Sgt Tinggi | C23: ≥18 | D23: Perfeksionis ekstrem. Sangat cocok LO senior & quality control dokumen.
B25: I — INFLUENCE — Cara mempengaruhi & berhubungan dengan orang lain
B26: Level | C26: Range | D26: Interpretasi & Implikasi Rekrutmen
B27: Rendah | C27: < 9 | D27: Introvert, tidak nyaman jadi pusat perhatian. Kurang cocok PLA & Marketing.
B28: Sedang | C28: 9–13 | D28: Komunikasi cukup baik, bisa handle klien dengan training. CRM entry-level.
B29: Tinggi | C29: 14–17 | D29: Komunikatif, persuasif, hangat. Sangat cocok CRM, PLA, Marketing.
B30: Sgt Tinggi | C30: ≥18 | D30: Karismatik, sangat persuasif. Ideal Marketing lead & senior PLA.
B32: 📌 Tips HR: Lihat kombinasi 2 dimensi tertinggi, bukan hanya 1 dimensi. Profil terbaik selalu kombinasi (mis. C+D untuk LO, I+S untuk CRM).
